Workbook

Sheet Lookup
B2: MASTER
B3: Sl. No. | C3: Bus Stop ID | D3: Bus Stop Locations | E3: Type | G3: Sl. No. | H3: Bus Stop ID | I3: Type "A" Bus Stop Locations | K3: Sl. No. | L3: Bus Stop ID | M3: Type "B" Bus Stop Locations | O3: Sl. No. | P3: Bus Stop ID | Q3: Type "C" Bus Stop Locations | S3: Service Type
B4: 1 | C4: 6291 | D4: Glenn View Station at Walmart | E4: A | G4: 1 | H4: 5774 | I4: Durham Station | K4: 1 | L4: 5169 | M4: Morehead Ave at Moreland Ave (EB) | O4: 1 | P4: 1866 | Q4: NC 54 at Triangle Dr (EB) | S4: Inspected -Found all OK
B5: 2 | C5: 5445 | D5: Raynor St at The Village (WB) | E5: A | G5: 2 | H5: 6291 | I5: Glenn View Station at Walmart | K5: 2 | L5: 5570 | M5: Garrett Rd at Durham-Chapel Hill Blvd ( | O5: 2 | P5: 6603 | Q5: New Castle Rd at Wyldewood Rd (NB) | S5: Cleaning + Trash Removal
B6: 3 | C6: 1406 | D6: Renaissance Pkwy at Southpoint Mall | E6: A | G6: 3 | H6: 5445 | I6: Raynor St at The Village (WB) | K6: 3 | L6: 5690 | M6: NC 54 at NC 55 (EB) | O6: 3 | P6: 5281 | Q6: Dearborn Dr at Maplewood Dr (SB) | S6: Damage Repair
B7: 4 | C7: 6146 | D7: Fayetteville St at Pilot St (NB) | E7: A | G7: 4 | H7: 1406 | I7: Renaissance Pkwy at Southpoint Mall | K7: 4 | L7: 5701 | M7: Fayetteville St at Price Ave | O7: 4 | P7: 6627 | Q7: NC 55 at Service Station | S7: landscaping
B8: 5 | C8: 5148 | D8: E Main St at Alston Ave (WB) | E8: A | G8: 5 | H8: 6146 | I8: Fayetteville St at Pilot St (NB) | K8: 5 | L8: 6495 | M8: Martin Luther King Jr Pkwy at Bay Point | O8: 5 | P8: 5816 | Q8: Fayetteville St at Dunstan St | S8: Power wash
B9: 6 | C9: 5663 | D9: New Hope Commons | E9: A | G9: 6 | H9: 5148 | I9: E Main St at Alston Ave (WB) | K9: 6 | L9: 5718 | M9: LaSalle St at Campus Walk Dr (Holly Hil | O9: 6 | P9: 6473 | Q9: Chapel Hill Rd at Valley Terrace (NB) | S9: Others
B10: 7 | C10: 6203 | D10: Horton Rd at Guess Rd (Harris Teeter) | E10: A | G10: 7 | H10: 5663 | I10: New Hope Commons | K10: 7 | L10: 6663 | M10: Fayetteville Rd at Hillside High School | O10: 7 | P10: 5139 | Q10: Gregson St at Dacian Ave
B11: 8 | C11: 5513 | D11: Roxboro Rd at Horton Rd | E11: A | G11: 8 | H11: 6203 | I11: Horton Rd at Guess Rd (Harris Teeter) | K11: 8 | L11: 6317 | M11: Pettigrew St at Mangum St (EB) | O11: 8 | P11: 5700 | Q11: Roxboro St at Summit St
B12: 9 | C12: 5394 | D12: Chapel Hill Rd at Palmer St (EB) | E12: A | G12: 9 | H12: 5513 | I12: Roxboro Rd at Horton Rd | K12: 9 | L12: 5999 | M12: Chapel Hill Rd at W Cornwallis Rd (NB) | O12: 9 | P12: 6210 | Q12: Hillandale Rd at Pinetree Ct
B13: 10 | C13: 6297 | D13: Roxboro Rd at Liberty St | E13: A | G13: 10 | H13: 5394 | I13: Chapel Hill Rd at Palmer St (EB) | K13: 10 | L13: 6306 | M13: E Main St at Corcoran St (EB) | O13: 10 | P13: 5584 | Q13: Hardee St at Fiske St
B14: 11 | C14: 6068 | D14: Erwin Rd at Downing St (WB) | E14: A | G14: 11 | H14: 6297 | I14: Roxboro Rd at Liberty St | K14: 11 | L14: 6390 | M14: Main St at Broad St (WB) | O14: 11 | P14: 5499 | Q14: Meriwether Dr at Pickwick Trail (NB)
B15: 12 | C15: 6095 | D15: Duke Regional Hospital (SB) | E15: A | G15: 12 | H15: 6068 | I15: Erwin Rd at Downing St (WB) | K15: 12 | L15: 5864 | M15: University Dr at Hill St | O15: 12 | P15: 5340 | Q15: Morehead Ave at Kent St (WB)
B16: 13 | C16: 6620 | D16: Garrett Rd at Durham-Chapel Hill Blvd ( | E16: A | G16: 13 | H16: 6095 | I16: Duke Regional Hospital (SB) | K16: 13 | L16: 5983 | M16: Duke St at Kinder Care | O16: 13 | P16: 5648 | Q16: LaSalle St at Campus Walk Ave (Belmont
B17: 14 | C17: 6309 | D17: Dillard St at E Main St (Urban Ministri | E17: A | G17: 14 | H17: 6620 | I17: Garrett Rd at Durham-Chapel Hill Blvd ( | K17: 14 | L17: 5233 | M17: Freeman Rd at Clayton Rd (Southern HS) | O17: 14 | P17: 6605 | Q17: Horton Rd at Delbert Ave (WB)
B18: 15 | C18: 6104 | D18: Fulton St at Erwin Rd (Duke Hospital) | E18: A | G18: 15 | H18: 6309 | I18: Dillard St at E Main St (Urban Ministri | K18: 15 | L18: 5313 | M18: Alston Ave at Lawson St (SB) | O18: 15 | P18: 6530 | Q18: Junction Rd at Ross Rd
B19: 16 | C19: 6489 | D19: Raynor St at The Village (EB) | E19: A | G19: 16 | H19: 6104 | I19: Fulton St at Erwin Rd (Duke Hospital) | K19: 16 | L19: 5162 | M19: Willard St at Yancey St (Ramada Inn) | O19: 16 | P19: 5325 | Q19: Meriwether Dr at Carver Pond Apts
B20: 17 | C20: 5654 | D20: Horton Rd at Roxboro Rd | E20: A | G20: 17 | H20: 6489 | I20: Raynor St at The Village (EB) | K20: 17 | L20: 6387 | M20: Main St at Gregson St (WB) | O20: 17 | P20: 6730 | Q20: WEST AVE AT HEBRON RD
B21: 18 | C21: 5653 | D21: Fayetteville St at Riddle Rd (NB) | E21: A | G21: 18 | H21: 5654 | I21: Horton Rd at Roxboro Rd | K21: 18 | L21: 5118 | M21: Martin Luther King Jr Pkwy at Lake Camp | O21: 18 | P21: 6336 | Q21: Gregson St at Main St (Brightleaf Squar
... B152: 149 | C152: 5570 | D152: Garrett Rd at Durham-Chapel Hill Blvd ( | E152: B | G152: 149 | H152: 5396 | I152: Fayetteville St at Red Oak Ave (NB) | K152: 149 | L152: 5876 | M152: Ross Rd at Melbourne St | O152: 149 | P152: 5206 | Q152: Lawson St at Rosewood St (Eastbound)
B153: 150 | C153: 5690 | D153: NC 54 at NC 55 (EB) | E153: B | K153: 150 | L153: 5215 | M153: Fayetteville St at Lawson St (SB) | O153: 150 | P153: 5368 | Q153: Meriwether Dr at E Carver St (SB)
B154: 151 | C154: 5701 | D154: Fayetteville St at Price Ave | E154: B | K154: 151 | L154: 5285 | M154: Chapel Hill Rd at Valley Terrace (SB) | O154: 151 | P154: 5837 | Q154: Roxboro Rd at Infinity Rd
B155: 152 | C155: 6495 | D155: Martin Luther King Jr Pkwy at Bay Point | E155: B | K155: 152 | L155: 5947 | M155: E Weaver St at Cornwallis Rd | O155: 152 | P155: 6660 | Q155: Taylor St at Gary St (WB)
B156: 153 | C156: 5718 | D156: LaSalle St at Campus Walk Dr (Holly Hil | E156: B | K156: 153 | L156: 6270 | M156: TW Alexander Dr at Creekside Townhomes | O156: 153 | P156: 6664 | Q156: TW Alexander Dr at Fun Park Dr
B157: 154 | C157: 6663 | D157: Fayetteville Rd at Hillside High School | E157: B | K157: 154 | L157: 5102 | M157: Shirley St at Crest St | O157: 154 | P157: 5857 | Q157: Riddle Rd at Triangle Day Care (NB)
B158: 155 | C158: 6317 | D158: Pettigrew St at Mangum St (EB) | E158: B | K158: 155 | L158: 6599 | M158: Lawson St at Concord St (WB) | O158: 155 | P158: 5316 | Q158: Lawson St at DTCC Public Safety (EB)
B159: 156 | C159: 5999 | D159: Chapel Hill Rd at W Cornwallis Rd (NB) | E159: B | K159: 156 | L159: 5996 | M159: Meriwether Dr at Old Oxford Rd (NB) | O159: 156 | P159: 6243 | Q159: W Geer St at Rigsbee Ave
B160: 157 | C160: 6306 | D160: E Main St at Corcoran St (EB) | E160: B | K160: 157 | L160: 6258 | M160: Fayetteville Rd at Tralea Dr (Mt Zion C | O160: 157 | P160: 5860 | Q160: Roxboro Rd at Channing Ave (SB)
B161: 158 | C161: 6390 | D161: Main St at Broad St (WB) | E161: B | K161: 158 | L161: 6169 | M161: LaSalle St at Duke Manor Apts (NB) | O161: 158 | P161: 1161 | Q161: NC 54 at Residence Inn Blvd (EB)
B162: 159 | C162: 5864 | D162: University Dr at Hill St | E162: B | K162: 159 | L162: 5091 | M162: E Club Blvd at Glenbrook Dr (SB) | O162: 159 | P162: 5370 | Q162: Dearborn Dr at Martin St
B163: 160 | C163: 5983 | D163: Duke St at Kinder Care | E163: B | K163: 160 | L163: 5357 | M163: Fayetteville St at Cecil St (SB) | O163: 160 | P163: 6073 | Q163: Gary St at N Miami Blvd (SB)
B164: 161 | C164: 5233 | D164: Freeman Rd at Clayton Rd (Southern HS) | E164: B | K164: 161 | L164: 5498 | M164: Holloway St at Guthrie Ave (EB) | O164: 161 | P164: 789999 | Q164: DUKE ST AT HOLT SCHOOL RD
... B205: 202 | C205: 5042 | D205: University Dr at Weymouth St (WB) | E205: B | K205: 202 | L205: 5115 | M205: Alston Ave at Dayton St (SB) | O205: 202 | P205: 5826 | Q205: Roxboro Rd at Ellerbee St (SB)
B206: 203 | C206: 5319 | D206: Old Oxford Rd at Danube Ln (EB) | E206: B | O206: 203 | P206: 5938 | Q206: S Roxboro St at Erie St (SB)
B207: 204 | C207: 6729 | D207: DANUBE LN AT HEBRON RD | E207: B | O207: 204 | P207: 5672 | Q207: Fayetteville St at Timothy Ave (SB)
B208: 205 | C208: 5119 | D208: Roxboro Rd at Ellerbee St (NB) | E208: B | O208: 205 | P208: 5616 | Q208: Cornwallis Rd at Yorktown Ave (SB)
B209: 206 | C209: 6246 | D209: Geer St at Rigsbee Ave | E209: B | O209: 206 | P209: 6137 | Q209: Capps St at Bacon St (EB)
B210: 207 | C210: 6446 | D210: S Alston Ave at Capitola Dr (SB) | E210: B | O210: 207 | P210: 5650 | Q210: Durham-Chapel Hill Blvd at Hope Valley
B211: 208 | C211: 5679 | D211: Crutchfield St at Crabtree Ave | E211: B | O211: 208 | P211: 6263 | Q211: Miami Blvd at Ellis Rd (Bethesda Elemen
...

Sheet JAN 25
B1: BUS STOP MAINTENANCE TRACKER JANUARY 2025
B3: Bus Stop ID | C3: Bus Stop Locations | D3: Type | E3: Requested Service | F3: Service Request Received on | G3: Work Order sent to Contractor on | H3: Work Executed on (Mandatory) | I3: Requested Service | J3: Service Request Received on | K3: Work Order sent to Contractor on | L3: Work Executed on (Mandatory) | M3: Requested Service | N3: Service Request Received on | O3: Work Order sent to Contractor on | P3: Work Executed on (Mandatory) | Q3: Total number of Executions per Bus Stop
B4: =Lookup!C443 -> 1072 | C4: =Lookup!D443 -> Old Chapel Hill Rd at Garrett Rd (EB) | D4: =Lookup!E443 -> C | Q4: =IF(H4="",0,1)+IF(L4="",0,1)+IF(P4="",0,1) -> 0
B5: =Lookup!C776 -> 1074 | C5: =Lookup!D776 -> University Dr at American Red Cross | D5: =Lookup!E776 -> C | Q5: =IF(H5="",0,1)+IF(L5="",0,1)+IF(P5="",0,1) -> 0
B6: =Lookup!C273 -> 1075 | C6: =Lookup!D273 -> University Dr at Ivy Creek Blvd | D6: =Lookup!E273 -> B | Q6: =IF(H6="",0,1)+IF(L6="",0,1)+IF(P6="",0,1) -> 0
B7: =Lookup!C435 -> 1160 | C7: =Lookup!D435 -> NC 54 at Blanchard Rd (EB) | D7: =Lookup!E435 -> C | Q7: =IF(H7="",0,1)+IF(L7="",0,1)+IF(P7="",0,1) -> 0
B8: =Lookup!C510 -> 1161 | C8: =Lookup!D510 -> NC 54 at Residence Inn Blvd (EB) | D8: =Lookup!E510 -> C | Q8: =IF(H8="",0,1)+IF(L8="",0,1)+IF(P8="",0,1) -> 0
B9: =Lookup!C588 -> 1171 | C9: =Lookup!D588 -> NC 54 at Blanchard Rd (WB) | D9: =Lookup!E588 -> C | Q9: =IF(H9="",0,1)+IF(L9="",0,1)+IF(P9="",0,1) -> 0
B10: =Lookup!C545 -> 1175 | C10: =Lookup!D545 -> NC 54 at Fayetteville Rd (Duke Health) | D10: =Lookup!E545 -> C | Q10: =IF(H10="",0,1)+IF(L10="",0,1)+IF(P10="",0,1) -> 0
B11: =Lookup!C735 -> 1221 | C11: =Lookup!D735 -> Slater Rd at Page Rd (Imperial Point) | D11: =Lookup!E735 -> C | Q11: =IF(H11="",0,1)+IF(L11="",0,1)+IF(P11="",0,1) -> 0
B12: =Lookup!C877 -> 1222 | C12: =Lookup!D877 -> Slater Rd at Emperor Blvd (Chelsea Place) | D12: =Lookup!E877 -> C | Q12: =IF(H12="",0,1)+IF(L12="",0,1)+IF(P12="",0,1) -> 0
B13: =Lookup!C6 -> 1406 | C13: =Lookup!D6 -> Renaissance Pkwy at Southpoint Mall | D13: =Lookup!E6 -> A | Q13: =IF(H13="",0,1)+IF(L13="",0,1)+IF(P13="",0,1) -> 0
B14: =Lookup!C660 -> 1499 | C14: =Lookup!D660 -> Slater Rd at Page Rd (Coastal Credit Union) | D14: =Lookup!E660 -> C | Q14: =IF(H14="",0,1)+IF(L14="",0,1)+IF(P14="",0,1) -> 0
B15: =Lookup!C336 -> 1553 | C15: =Lookup!D336 -> Erwin Rd at Towerview Rd | D15: =Lookup!E336 -> B | Q15: =IF(H15="",0,1)+IF(L15="",0,1)+IF(P15="",0,1) -> 0
B16: =Lookup!C817 -> 1556 | C16: =Lookup!D817 -> NC 54 at New Millennium Way (EB) | D16: =Lookup!E817 -> C | Q16: =IF(H16="",0,1)+IF(L16="",0,1)+IF(P16="",0,1) -> 0
B17: =Lookup!C749 -> 1557 | C17: =Lookup!D749 -> NC 54 at New Millennium Way (WB) | D17: =Lookup!E749 -> C | Q17: =IF(H17="",0,1)+IF(L17="",0,1)+IF(P17="",0,1) -> 0
B18: =Lookup!C274 -> 1558 | C18: =Lookup!D274 -> Slater Rd at Creekstone Dr (Duke Medicine) | D18: =Lookup!E274 -> B | Q18: =IF(H18="",0,1)+IF(L18="",0,1)+IF(P18="",0,1) -> 0
B19: =Lookup!C892 -> 1563 | C19: =Lookup!D892 -> Slater Rd at Emperor Blvd (Bright Horiz | D19: =Lookup!E892 -> C | Q19: =IF(H19="",0,1)+IF(L19="",0,1)+IF(P19="",0,1) -> 0
B20: =Lookup!C565 -> 1566 | C20: =Lookup!D565 -> Slater Rd at S Miami Blvd (Zaxbys) | D20: =Lookup!E565 -> C | Q20: =IF(H20="",0,1)+IF(L20="",0,1)+IF(P20="",0,1) -> 0
B21: =Lookup!C869 -> 1732 | C21: =Lookup!D869 -> Stirrup Creek at Twin Creek Ct | D21: =Lookup!E869 -> C | Q21: =IF(H21="",0,1)+IF(L21="",0,1)+IF(P21="",0,1) -> 0
B22: =Lookup!C876 -> 1776 | C22: =Lookup!D876 -> Slater Rd at GoTriangle Admin Office | D22: =Lookup!E876 -> C | Q22: =IF(H22="",0,1)+IF(L22="",0,1)+IF(P22="",0,1) -> 0
B23: =Lookup!C777 -> 1777 | C23: =Lookup!D777 -> Slater Rd at Sheraton Hotel | D23: =Lookup!E777 -> C | Q23: =IF(H23="",0,1)+IF(L23="",0,1)+IF(P23="",0,1) -> 0
B24: =Lookup!C500 -> 1781 | C24: =Lookup!D500 -> NC 54 at Revere Rd (EB) | D24: =Lookup!E500 -> C | Q24: =IF(H24="",0,1)+IF(L24="",0,1)+IF(P24="",0,1) -> 0
B25: =Lookup!C738 -> 1804 | C25: =Lookup!D738 -> Renaissance Pkwy at Leonardo Dr (WB) | D25: =Lookup!E738 -> C | Q25: =IF(H25="",0,1)+IF(L25="",0,1)+IF(P25="",0,1) -> 0
B26: =Lookup!C374 -> 1805 | C26: =Lookup!D374 -> NC 54 at Amhurst St | D26: =Lookup!E374 -> C | Q26: =IF(H26="",0,1)+IF(L26="",0,1)+IF(P26="",0,1) -> 0
B27: =Lookup!C893 -> 1860 | C27: =Lookup!D893 -> NC 54 at Park Dr (EB) | D27: =Lookup!E893 -> C | Q27: =IF(H27="",0,1)+IF(L27="",0,1)+IF(P27="",0,1) -> 0
B28: =Lookup!C888 -> 1861 | C28: =Lookup!D888 -> NC 54 at Park Dr (First Citizens Bank) | D28: =Lookup!E888 -> C | Q28: =IF(H28="",0,1)+IF(L28="",0,1)+IF(P28="",0,1) -> 0
B29: =Lookup!C879 -> 1863 | C29: =Lookup!D879 -> NC 54 at Park Office Dr (The Frontier) | D29: =Lookup!E879 -> C | Q29: =IF(H29="",0,1)+IF(L29="",0,1)+IF(P29="",0,1) -> 0
B30: =Lookup!C857 -> 1864 | C30: =Lookup!D857 -> NC 54 at Research Triangle High School | D30: =Lookup!E857 -> C | Q30: =IF(H30="",0,1)+IF(L30="",0,1)+IF(P30="",0,1) -> 0
B31: =Lookup!C740 -> 1865 | C31: =Lookup!D740 -> NC 54 at Triangle Dr (WB) | D31: =Lookup!E740 -> C | Q31: =IF(H31="",0,1)+IF(L31="",0,1)+IF(P31="",0,1) -> 0
B32: =Lookup!C353 -> 1866 | C32: =Lookup!D353 -> NC 54 at Triangle Dr (EB) | D32: =Lookup!E353 -> C | Q32: =IF(H32="",0,1)+IF(L32="",0,1)+IF(P32="",0,1) -> 0
B33: =Lookup!C202 -> 1892 | C33: =Lookup!D202 -> Fayetteville Rd at Renaissance Pkwy | D33: =Lookup!E202 -> B | Q33: =IF(H33="",0,1)+IF(L33="",0,1)+IF(P33="",0,1) -> 0
B34: =Lookup!C479 -> 1893 | C34: =Lookup!D479 -> NC 54 at The Hamptons Apts (EB) | D34: =Lookup!E479 -> C | Q34: =IF(H34="",0,1)+IF(L34="",0,1)+IF(P34="",0,1) -> 0
B35: =Lookup!C61 -> 1901 | C35: =Lookup!D61 -> McFarland Dr at Witherspoon Blvd (Patte | D35: =Lookup!E61 -> A | Q35: =IF(H35="",0,1)+IF(L35="",0,1)+IF(P35="",0,1) -> 0
B36: =Lookup!C595 -> 1914 | C36: =Lookup!D595 -> University Dr at University Pl (EB) | D36: =Lookup!E595 -> C | Q36: =IF(H36="",0,1)+IF(L36="",0,1)+IF(P36="",0,1) -> 0
B37: =Lookup!C611 -> 5002 | C37: =Lookup!D611 -> Riddle Rd at Ancroft Ave (NB) | D37: =Lookup!E611 -> C | Q37: =IF(H37="",0,1)+IF(L37="",0,1)+IF(P37="",0,1) -> 0
B38: =Lookup!C201 -> 5004 | C38: =Lookup!D201 -> Alston Ave at Main St | D38: =Lookup!E201 -> B | Q38: =IF(H38="",0,1)+IF(L38="",0,1)+IF(P38="",0,1) -> 0
B39: =Lookup!C838 -> 5005 | C39: =Lookup!D838 -> Cornwallis Rd at Industry Ln | D39: =Lookup!E838 -> C | Q39: =IF(H39="",0,1)+IF(L39="",0,1)+IF(P39="",0,1) -> 0
B40: =Lookup!C889 -> 5006 | C40: =Lookup!D889 -> Alston Ave at Durham Freeway (NB) | D40: =Lookup!E889 -> C | Q40: =IF(H40="",0,1)+IF(L40="",0,1)+IF(P40="",0,1) -> 0
B41: =Lookup!C240 -> 5008 | C41: =Lookup!D240 -> S Alston Ave at Massey Ave (NB) | D41: =Lookup!E240 -> B | Q41: =IF(H41="",0,1)+IF(L41="",0,1)+IF(P41="",0,1) -> 0
...

Sheet FEB 25
B1: BUS STOP MAINTENANCE TRACKER FEBRUARY 2025
B3: Bus Stop ID | C3: Bus Stop Locations | D3: Type | E3: Requested Service | F3: Service Request Received on | G3: Work Order sent to Contractor on | H3: Work Executed on (Mandatory) | I3: Requested Service | J3: Service Request Received on | K3: Work Order sent to Contractor on | L3: Work Executed on (Mandatory) | M3: Requested Service | N3: Service Request Received on | O3: Work Order sent to Contractor on | P3: Work Executed on (Mandatory) | Q3: Total number of Executions per Bus Stop
B4: =Lookup!C443 -> 1072 | C4: =Lookup!D443 -> Old Chapel Hill Rd at Garrett Rd (EB) | D4: =Lookup!E443 -> C | Q4: =IF(H4="",0,1)+IF(L4="",0,1)+IF(P4="",0,1) -> 0
B5: =Lookup!C776 -> 1074 | C5: =Lookup!D776 -> University Dr at American Red Cross | D5: =Lookup!E776 -> C | Q5: =IF(H5="",0,1)+IF(L5="",0,1)+IF(P5="",0,1) -> 0
B6: =Lookup!C273 -> 1075 | C6: =Lookup!D273 -> University Dr at Ivy Creek Blvd | D6: =Lookup!E273 -> B | Q6: =IF(H6="",0,1)+IF(L6="",0,1)+IF(P6="",0,1) -> 0
B7: =Lookup!C435 -> 1160 | C7: =Lookup!D435 -> NC 54 at Blanchard Rd (EB) | D7: =Lookup!E435 -> C | Q7: =IF(H7="",0,1)+IF(L7="",0,1)+IF(P7="",0,1) -> 0
B8: =Lookup!C510 -> 1161 | C8: =Lookup!D510 -> NC 54 at Residence Inn Blvd (EB) | D8: =Lookup!E510 -> C | Q8: =IF(H8="",0,1)+IF(L8="",0,1)+IF(P8="",0,1) -> 0
B9: =Lookup!C588 -> 1171 | C9: =Lookup!D588 -> NC 54 at Blanchard Rd (WB) | D9: =Lookup!E588 -> C | Q9: =IF(H9="",0,1)+IF(L9="",0,1)+IF(P9="",0,1) -> 0
B10: =Lookup!C545 -> 1175 | C10: =Lookup!D545 -> NC 54 at Fayetteville Rd (Duke Health) | D10: =Lookup!E545 -> C | Q10: =IF(H10="",0,1)+IF(L10="",0,1)+IF(P10="",0,1) -> 0
B11: =Lookup!C735 -> 1221 | C11: =Lookup!D735 -> Slater Rd at Page Rd (Imperial Point) | D11: =Lookup!E735 -> C | Q11: =IF(H11="",0,1)+IF(L11="",0,1)+IF(P11="",0,1) -> 0
B12: =Lookup!C877 -> 1222 | C12: =Lookup!D877 -> Slater Rd at Emperor Blvd (Chelsea Place) | D12: =Lookup!E877 -> C | Q12: =IF(H12="",0,1)+IF(L12="",0,1)+IF(P12="",0,1) -> 0
B13: =Lookup!C6 -> 1406 | C13: =Lookup!D6 -> Renaissance Pkwy at Southpoint Mall | D13: =Lookup!E6 -> A | Q13: =IF(H13="",0,1)+IF(L13="",0,1)+IF(P13="",0,1) -> 0
B14: =Lookup!C660 -> 1499 | C14: =Lookup!D660 -> Slater Rd at Page Rd (Coastal Credit Union) | D14: =Lookup!E660 -> C | Q14: =IF(H14="",0,1)+IF(L14="",0,1)+IF(P14="",0,1) -> 0
B15: =Lookup!C336 -> 1553 | C15: =Lookup!D336 -> Erwin Rd at Towerview Rd | D15: =Lookup!E336 -> B | Q15: =IF(H15="",0,1)+IF(L15="",0,1)+IF(P15="",0,1) -> 0
B16: =Lookup!C817 -> 1556 | C16: =Lookup!D817 -> NC 54 at New Millennium Way (EB) | D16: =Lookup!E817 -> C | Q16: =IF(H16="",0,1)+IF(L16="",0,1)+IF(P16="",0,1) -> 0
B17: =Lookup!C749 -> 1557 | C17: =Lookup!D749 -> NC 54 at New Millennium Way (WB) | D17: =Lookup!E749 -> C | Q17: =IF(H17="",0,1)+IF(L17="",0,1)+IF(P17="",0,1) -> 0
B18: =Lookup!C274 -> 1558 | C18: =Lookup!D274 -> Slater Rd at Creekstone Dr (Duke Medicine) | D18: =Lookup!E274 -> B | Q18: =IF(H18="",0,1)+IF(L18="",0,1)+IF(P18="",0,1) -> 0
B19: =Lookup!C892 -> 1563 | C19: =Lookup!D892 -> Slater Rd at Emperor Blvd (Bright Horiz | D19: =Lookup!E892 -> C | Q19: =IF(H19="",0,1)+IF(L19="",0,1)+IF(P19="",0,1) -> 0
B20: =Lookup!C565 -> 1566 | C20: =Lookup!D565 -> Slater Rd at S Miami Blvd (Zaxbys) | D20: =Lookup!E565 -> C | Q20: =IF(H20="",0,1)+IF(L20="",0,1)+IF(P20="",0,1) -> 0
B21: =Lookup!C869 -> 1732 | C21: =Lookup!D869 -> Stirrup Creek at Twin Creek Ct | D21: =Lookup!E869 -> C | Q21: =IF(H21="",0,1)+IF(L21="",0,1)+IF(P21="",0,1) -> 0
B22: =Lookup!C876 -> 1776 | C22: =Lookup!D876 -> Slater Rd at GoTriangle Admin Office | D22: =Lookup!E876 -> C | Q22: =IF(H22="",0,1)+IF(L22="",0,1)+IF(P22="",0,1) -> 0
B23: =Lookup!C777 -> 1777 | C23: =Lookup!D777 -> Slater Rd at Sheraton Hotel | D23: =Lookup!E777 -> C | Q23: =IF(H23="",0,1)+IF(L23="",0,1)+IF(P23="",0,1) -> 0
B24: =Lookup!C500 -> 1781 | C24: =Lookup!D500 -> NC 54 at Revere Rd (EB) | D24: =Lookup!E500 -> C | Q24: =IF(H24="",0,1)+IF(L24="",0,1)+IF(P24="",0,1) -> 0
B25: =Lookup!C738 -> 1804 | C25: =Lookup!D738 -> Renaissance Pkwy at Leonardo Dr (WB) | D25: =Lookup!E738 -> C | Q25: =IF(H25="",0,1)+IF(L25="",0,1)+IF(P25="",0,1) -> 0
B26: =Lookup!C374 -> 1805 | C26: =Lookup!D374 -> NC 54 at Amhurst St | D26: =Lookup!E374 -> C | Q26: =IF(H26="",0,1)+IF(L26="",0,1)+IF(P26="",0,1) -> 0
B27: =Lookup!C893 -> 1860 | C27: =Lookup!D893 -> NC 54 at Park Dr (EB) | D27: =Lookup!E893 -> C | Q27: =IF(H27="",0,1)+IF(L27="",0,1)+IF(P27="",0,1) -> 0
B28: =Lookup!C888 -> 1861 | C28: =Lookup!D888 -> NC 54 at Park Dr (First Citizens Bank) | D28: =Lookup!E888 -> C | Q28: =IF(H28="",0,1)+IF(L28="",0,1)+IF(P28="",0,1) -> 0
B29: =Lookup!C879 -> 1863 | C29: =Lookup!D879 -> NC 54 at Park Office Dr (The Frontier) | D29: =Lookup!E879 -> C | Q29: =IF(H29="",0,1)+IF(L29="",0,1)+IF(P29="",0,1) -> 0
B30: =Lookup!C857 -> 1864 | C30: =Lookup!D857 -> NC 54 at Research Triangle High School | D30: =Lookup!E857 -> C | Q30: =IF(H30="",0,1)+IF(L30="",0,1)+IF(P30="",0,1) -> 0
B31: =Lookup!C740 -> 1865 | C31: =Lookup!D740 -> NC 54 at Triangle Dr (WB) | D31: =Lookup!E740 -> C | Q31: =IF(H31="",0,1)+IF(L31="",0,1)+IF(P31="",0,1) -> 0
B32: =Lookup!C353 -> 1866 | C32: =Lookup!D353 -> NC 54 at Triangle Dr (EB) | D32: =Lookup!E353 -> C | Q32: =IF(H32="",0,1)+IF(L32="",0,1)+IF(P32="",0,1) -> 0
B33: =Lookup!C202 -> 1892 | C33: =Lookup!D202 -> Fayetteville Rd at Renaissance Pkwy | D33: =Lookup!E202 -> B | Q33: =IF(H33="",0,1)+IF(L33="",0,1)+IF(P33="",0,1) -> 0
B34: =Lookup!C479 -> 1893 | C34: =Lookup!D479 -> NC 54 at The Hamptons Apts (EB) | D34: =Lookup!E479 -> C | Q34: =IF(H34="",0,1)+IF(L34="",0,1)+IF(P34="",0,1) -> 0
B35: =Lookup!C61 -> 1901 | C35: =Lookup!D61 -> McFarland Dr at Witherspoon Blvd (Patte | D35: =Lookup!E61 -> A | Q35: =IF(H35="",0,1)+IF(L35="",0,1)+IF(P35="",0,1) -> 0
B36: =Lookup!C595 -> 1914 | C36: =Lookup!D595 -> University Dr at University Pl (EB) | D36: =Lookup!E595 -> C | Q36: =IF(H36="",0,1)+IF(L36="",0,1)+IF(P36="",0,1) -> 0
B37: =Lookup!C611 -> 5002 | C37: =Lookup!D611 -> Riddle Rd at Ancroft Ave (NB) | D37: =Lookup!E611 -> C | Q37: =IF(H37="",0,1)+IF(L37="",0,1)+IF(P37="",0,1) -> 0
B38: =Lookup!C201 -> 5004 | C38: =Lookup!D201 -> Alston Ave at Main St | D38: =Lookup!E201 -> B | Q38: =IF(H38="",0,1)+IF(L38="",0,1)+IF(P38="",0,1) -> 0
B39: =Lookup!C838 -> 5005 | C39: =Lookup!D838 -> Cornwallis Rd at Industry Ln | D39: =Lookup!E838 -> C | Q39: =IF(H39="",0,1)+IF(L39="",0,1)+IF(P39="",0,1) -> 0
B40: =Lookup!C889 -> 5006 | C40: =Lookup!D889 -> Alston Ave at Durham Freeway (NB) | D40: =Lookup!E889 -> C | Q40: =IF(H40="",0,1)+IF(L40="",0,1)+IF(P40="",0,1) -> 0
B41: =Lookup!C240 -> 5008 | C41: =Lookup!D240 -> S Alston Ave at Massey Ave (NB) | D41: =Lookup!E240 -> B | Q41: =IF(H41="",0,1)+IF(L41="",0,1)+IF(P41="",0,1) -> 0
...

Sheet MAR 25
B1: BUS STOP MAINTENANCE TRACKER MARCH 2025
B3: Bus Stop ID | C3: Bus Stop Locations | D3: Type | E3: Requested Service | F3: Service Request Received on | G3: Work Order sent to Contractor on | H3: Work Executed on (Mandatory) | I3: Requested Service | J3: Service Request Received on | K3: Work Order sent to Contractor on | L3: Work Executed on (Mandatory) | M3: Requested Service | N3: Service Request Received on | O3: Work Order sent to Contractor on | P3: Work Executed on (Mandatory) | Q3: Total number of Executions per Bus Stop
B4: =Lookup!C443 -> 1072 | C4: =Lookup!D443 -> Old Chapel Hill Rd at Garrett Rd (EB) | D4: =Lookup!E443 -> C | Q4: =IF(H4="",0,1)+IF(L4="",0,1)+IF(P4="",0,1) -> 0
B5: =Lookup!C776 -> 1074 | C5: =Lookup!D776 -> University Dr at American Red Cross | D5: =Lookup!E776 -> C | Q5: =IF(H5="",0,1)+IF(L5="",0,1)+IF(P5="",0,1) -> 0
B6: =Lookup!C273 -> 1075 | C6: =Lookup!D273 -> University Dr at Ivy Creek Blvd | D6: =Lookup!E273 -> B | Q6: =IF(H6="",0,1)+IF(L6="",0,1)+IF(P6="",0,1) -> 0
B7: =Lookup!C435 -> 1160 | C7: =Lookup!D435 -> NC 54 at Blanchard Rd (EB) | D7: =Lookup!E435 -> C | Q7: =IF(H7="",0,1)+IF(L7="",0,1)+IF(P7="",0,1) -> 0
B8: =Lookup!C510 -> 1161 | C8: =Lookup!D510 -> NC 54 at Residence Inn Blvd (EB) | D8: =Lookup!E510 -> C | Q8: =IF(H8="",0,1)+IF(L8="",0,1)+IF(P8="",0,1) -> 0
B9: =Lookup!C588 -> 1171 | C9: =Lookup!D588 -> NC 54 at Blanchard Rd (WB) | D9: =Lookup!E588 -> C | Q9: =IF(H9="",0,1)+IF(L9="",0,1)+IF(P9="",0,1) -> 0
B10: =Lookup!C545 -> 1175 | C10: =Lookup!D545 -> NC 54 at Fayetteville Rd (Duke Health) | D10: =Lookup!E545 -> C | Q10: =IF(H10="",0,1)+IF(L10="",0,1)+IF(P10="",0,1) -> 0
B11: =Lookup!C735 -> 1221 | C11: =Lookup!D735 -> Slater Rd at Page Rd (Imperial Point) | D11: =Lookup!E735 -> C | Q11: =IF(H11="",0,1)+IF(L11="",0,1)+IF(P11="",0,1) -> 0
B12: =Lookup!C877 -> 1222 | C12: =Lookup!D877 -> Slater Rd at Emperor Blvd (Chelsea Place) | D12: =Lookup!E877 -> C | Q12: =IF(H12="",0,1)+IF(L12="",0,1)+IF(P12="",0,1) -> 0
B13: =Lookup!C6 -> 1406 | C13: =Lookup!D6 -> Renaissance Pkwy at Southpoint Mall | D13: =Lookup!E6 -> A | Q13: =IF(H13="",0,1)+IF(L13="",0,1)+IF(P13="",0,1) -> 0
B14: =Lookup!C660 -> 1499 | C14: =Lookup!D660 -> Slater Rd at Page Rd (Coastal Credit Union) | D14: =Lookup!E660 -> C | Q14: =IF(H14="",0,1)+IF(L14="",0,1)+IF(P14="",0,1) -> 0
B15: =Lookup!C336 -> 1553 | C15: =Lookup!D336 -> Erwin Rd at Towerview Rd | D15: =Lookup!E336 -> B | Q15: =IF(H15="",0,1)+IF(L15="",0,1)+IF(P15="",0,1) -> 0
B16: =Lookup!C817 -> 1556 | C16: =Lookup!D817 -> NC 54 at New Millennium Way (EB) | D16: =Lookup!E817 -> C | Q16: =IF(H16="",0,1)+IF(L16="",0,1)+IF(P16="",0,1) -> 0
B17: =Lookup!C749 -> 1557 | C17: =Lookup!D749 -> NC 54 at New Millennium Way (WB) | D17: =Lookup!E749 -> C | Q17: =IF(H17="",0,1)+IF(L17="",0,1)+IF(P17="",0,1) -> 0
B18: =Lookup!C274 -> 1558 | C18: =Lookup!D274 -> Slater Rd at Creekstone Dr (Duke Medicine) | D18: =Lookup!E274 -> B | Q18: =IF(H18="",0,1)+IF(L18="",0,1)+IF(P18="",0,1) -> 0
B19: =Lookup!C892 -> 1563 | C19: =Lookup!D892 -> Slater Rd at Emperor Blvd (Bright Horiz | D19: =Lookup!E892 -> C | Q19: =IF(H19="",0,1)+IF(L19="",0,1)+IF(P19="",0,1) -> 0
B20: =Lookup!C565 -> 1566 | C20: =Lookup!D565 -> Slater Rd at S Miami Blvd (Zaxbys) | D20: =Lookup!E565 -> C | Q20: =IF(H20="",0,1)+IF(L20="",0,1)+IF(P20="",0,1) -> 0
B21: =Lookup!C869 -> 1732 | C21: =Lookup!D869 -> Stirrup Creek at Twin Creek Ct | D21: =Lookup!E869 -> C | Q21: =IF(H21="",0,1)+IF(L21="",0,1)+IF(P21="",0,1) -> 0
B22: =Lookup!C876 -> 1776 | C22: =Lookup!D876 -> Slater Rd at GoTriangle Admin Office | D22: =Lookup!E876 -> C | Q22: =IF(H22="",0,1)+IF(L22="",0,1)+IF(P22="",0,1) -> 0
B23: =Lookup!C777 -> 1777 | C23: =Lookup!D777 -> Slater Rd at Sheraton Hotel | D23: =Lookup!E777 -> C | Q23: =IF(H23="",0,1)+IF(L23="",0,1)+IF(P23="",0,1) -> 0
B24: =Lookup!C500 -> 1781 | C24: =Lookup!D500 -> NC 54 at Revere Rd (EB) | D24: =Lookup!E500 -> C | Q24: =IF(H24="",0,1)+IF(L24="",0,1)+IF(P24="",0,1) -> 0
B25: =Lookup!C738 -> 1804 | C25: =Lookup!D738 -> Renaissance Pkwy at Leonardo Dr (WB) | D25: =Lookup!E738 -> C | Q25: =IF(H25="",0,1)+IF(L25="",0,1)+IF(P25="",0,1) -> 0
B26: =Lookup!C374 -> 1805 | C26: =Lookup!D374 -> NC 54 at Amhurst St | D26: =Lookup!E374 -> C | Q26: =IF(H26="",0,1)+IF(L26="",0,1)+IF(P26="",0,1) -> 0
B27: =Lookup!C893 -> 1860 | C27: =Lookup!D893 -> NC 54 at Park Dr (EB) | D27: =Lookup!E893 -> C | Q27: =IF(H27="",0,1)+IF(L27="",0,1)+IF(P27="",0,1) -> 0
B28: =Lookup!C888 -> 1861 | C28: =Lookup!D888 -> NC 54 at Park Dr (First Citizens Bank) | D28: =Lookup!E888 -> C | Q28: =IF(H28="",0,1)+IF(L28="",0,1)+IF(P28="",0,1) -> 0
B29: =Lookup!C879 -> 1863 | C29: =Lookup!D879 -> NC 54 at Park Office Dr (The Frontier) | D29: =Lookup!E879 -> C | Q29: =IF(H29="",0,1)+IF(L29="",0,1)+IF(P29="",0,1) -> 0
B30: =Lookup!C857 -> 1864 | C30: =Lookup!D857 -> NC 54 at Research Triangle High School | D30: =Lookup!E857 -> C | Q30: =IF(H30="",0,1)+IF(L30="",0,1)+IF(P30="",0,1) -> 0
B31: =Lookup!C740 -> 1865 | C31: =Lookup!D740 -> NC 54 at Triangle Dr (WB) | D31: =Lookup!E740 -> C | Q31: =IF(H31="",0,1)+IF(L31="",0,1)+IF(P31="",0,1) -> 0
B32: =Lookup!C353 -> 1866 | C32: =Lookup!D353 -> NC 54 at Triangle Dr (EB) | D32: =Lookup!E353 -> C | Q32: =IF(H32="",0,1)+IF(L32="",0,1)+IF(P32="",0,1) -> 0
B33: =Lookup!C202 -> 1892 | C33: =Lookup!D202 -> Fayetteville Rd at Renaissance Pkwy | D33: =Lookup!E202 -> B | Q33: =IF(H33="",0,1)+IF(L33="",0,1)+IF(P33="",0,1) -> 0
B34: =Lookup!C479 -> 1893 | C34: =Lookup!D479 -> NC 54 at The Hamptons Apts (EB) | D34: =Lookup!E479 -> C | Q34: =IF(H34="",0,1)+IF(L34="",0,1)+IF(P34="",0,1) -> 0
B35: =Lookup!C61 -> 1901 | C35: =Lookup!D61 -> McFarland Dr at Witherspoon Blvd (Patte | D35: =Lookup!E61 -> A | Q35: =IF(H35="",0,1)+IF(L35="",0,1)+IF(P35="",0,1) -> 0
B36: =Lookup!C595 -> 1914 | C36: =Lookup!D595 -> University Dr at University Pl (EB) | D36: =Lookup!E595 -> C | Q36: =IF(H36="",0,1)+IF(L36="",0,1)+IF(P36="",0,1) -> 0
B37: =Lookup!C611 -> 5002 | C37: =Lookup!D611 -> Riddle Rd at Ancroft Ave (NB) | D37: =Lookup!E611 -> C | Q37: =IF(H37="",0,1)+IF(L37="",0,1)+IF(P37="",0,1) -> 0
B38: =Lookup!C201 -> 5004 | C38: =Lookup!D201 -> Alston Ave at Main St | D38: =Lookup!E201 -> B | Q38: =IF(H38="",0,1)+IF(L38="",0,1)+IF(P38="",0,1) -> 0
B39: =Lookup!C838 -> 5005 | C39: =Lookup!D838 -> Cornwallis Rd at Industry Ln | D39: =Lookup!E838 -> C | Q39: =IF(H39="",0,1)+IF(L39="",0,1)+IF(P39="",0,1) -> 0
B40: =Lookup!C889 -> 5006 | C40: =Lookup!D889 -> Alston Ave at Durham Freeway (NB) | D40: =Lookup!E889 -> C | Q40: =IF(H40="",0,1)+IF(L40="",0,1)+IF(P40="",0,1) -> 0
B41: =Lookup!C240 -> 5008 | C41: =Lookup!D240 -> S Alston Ave at Massey Ave (NB) | D41: =Lookup!E240 -> B | Q41: =IF(H41="",0,1)+IF(L41="",0,1)+IF(P41="",0,1) -> 0
...

Sheet APR 25
B1: BUS STOP MAINTENANCE TRACKER APRIL 28- May 2 2025
B3: Bus Stop ID | C3: Bus Stop Locations | D3: Type | E3: Requested Service | F3: Service Request Received on | G3: Work Order sent to Contractor on | H3: Work Executed on (Mandatory) | I3: Requested Service | J3: Service Request Received on | K3: Work Order sent to Contractor on | L3: Work Executed on (Mandatory) | M3: Requested Service | N3: Service Request Received on | O3: Work Order sent to Contractor on | P3: Work Executed on (Mandatory) | Q3: Total number of Executions per Bus Stop
B4: =Lookup!C443 -> 1072 | C4: =Lookup!D443 -> Old Chapel Hill Rd at Garrett Rd (EB) | D4: =Lookup!E443 -> C | Q4: =IF(H4="",0,1)+IF(L4="",0,1)+IF(P4="",0,1) -> 0
B5: =Lookup!C776 -> 1074 | C5: =Lookup!D776 -> University Dr at American Red Cross | D5: =Lookup!E776 -> C | Q5: =IF(H5="",0,1)+IF(L5="",0,1)+IF(P5="",0,1) -> 0
B6: =Lookup!C273 -> 1075 | C6: =Lookup!D273 -> University Dr at Ivy Creek Blvd | D6: =Lookup!E273 -> B | E6: Cleaning + Trash Removal | F6: 45775 | H6: 45775 | Q6: =IF(H6="",0,1)+IF(L6="",0,1)+IF(P6="",0,1) -> 1
B7: =Lookup!C435 -> 1160 | C7: =Lookup!D435 -> NC 54 at Blanchard Rd (EB) | D7: =Lookup!E435 -> C | Q7: =IF(H7="",0,1)+IF(L7="",0,1)+IF(P7="",0,1) -> 0
B8: =Lookup!C510 -> 1161 | C8: =Lookup!D510 -> NC 54 at Residence Inn Blvd (EB) | D8: =Lookup!E510 -> C | Q8: =IF(H8="",0,1)+IF(L8="",0,1)+IF(P8="",0,1) -> 0
B9: =Lookup!C588 -> 1171 | C9: =Lookup!D588 -> NC 54 at Blanchard Rd (WB) | D9: =Lookup!E588 -> C | Q9: =IF(H9="",0,1)+IF(L9="",0,1)+IF(P9="",0,1) -> 0
B10: =Lookup!C545 -> 1175 | C10: =Lookup!D545 -> NC 54 at Fayetteville Rd (Duke Health) | D10: =Lookup!E545 -> C | Q10: =IF(H10="",0,1)+IF(L10="",0,1)+IF(P10="",0,1) -> 0
B11: =Lookup!C735 -> 1221 | C11: =Lookup!D735 -> Slater Rd at Page Rd (Imperial Point) | D11: =Lookup!E735 -> C | Q11: =IF(H11="",0,1)+IF(L11="",0,1)+IF(P11="",0,1) -> 0
B12: =Lookup!C877 -> 1222 | C12: =Lookup!D877 -> Slater Rd at Emperor Blvd (Chelsea Place) | D12: =Lookup!E877 -> C | Q12: =IF(H12="",0,1)+IF(L12="",0,1)+IF(P12="",0,1) -> 0
B13: =Lookup!C6 -> 1406 | C13: =Lookup!D6 -> Renaissance Pkwy at Southpoint Mall | D13: =Lookup!E6 -> A | E13: Cleaning + Trash Removal | F13: 45776 | H13: 45776 | I13: Cleaning + Trash Removal | J13: 45778 | L13: 45778 | Q13: =IF(H13="",0,1)+IF(L13="",0,1)+IF(P13="",0,1) -> 2
B14: =Lookup!C660 -> 1499 | C14: =Lookup!D660 -> Slater Rd at Page Rd (Coastal Credit Union) | D14: =Lookup!E660 -> C | Q14: =IF(H14="",0,1)+IF(L14="",0,1)+IF(P14="",0,1) -> 0
B15: =Lookup!C336 -> 1553 | C15: =Lookup!D336 -> Erwin Rd at Towerview Rd | D15: =Lookup!E336 -> B | E15: Cleaning + Trash Removal | F15: 45775 | H15: 45775 | Q15: =IF(H15="",0,1)+IF(L15="",0,1)+IF(P15="",0,1) -> 1
B16: =Lookup!C817 -> 1556 | C16: =Lookup!D817 -> NC 54 at New Millennium Way (EB) | D16: =Lookup!E817 -> C | Q16: =IF(H16="",0,1)+IF(L16="",0,1)+IF(P16="",0,1) -> 0
B17: =Lookup!C749 -> 1557 | C17: =Lookup!D749 -> NC 54 at New Millennium Way (WB) | D17: =Lookup!E749 -> C | Q17: =IF(H17="",0,1)+IF(L17="",0,1)+IF(P17="",0,1) -> 0
B18: =Lookup!C274 -> 1558 | C18: =Lookup!D274 -> Slater Rd at Creekstone Dr (Duke Medicine) | D18: =Lookup!E274 -> B | E18: Cleaning + Trash Removal | F18: 45776 | H18: 45776 | Q18: =IF(H18="",0,1)+IF(L18="",0,1)+IF(P18="",0,1) -> 1
B19: =Lookup!C892 -> 1563 | C19: =Lookup!D892 -> Slater Rd at Emperor Blvd (Bright Horiz | D19: =Lookup!E892 -> C | Q19: =IF(H19="",0,1)+IF(L19="",0,1)+IF(P19="",0,1) -> 0
B20: =Lookup!C565 -> 1566 | C20: =Lookup!D565 -> Slater Rd at S Miami Blvd (Zaxbys) | D20: =Lookup!E565 -> C | Q20: =IF(H20="",0,1)+IF(L20="",0,1)+IF(P20="",0,1) -> 0
B21: =Lookup!C869 -> 1732 | C21: =Lookup!D869 -> Stirrup Creek at Twin Creek Ct | D21: =Lookup!E869 -> C | Q21: =IF(H21="",0,1)+IF(L21="",0,1)+IF(P21="",0,1) -> 0
B22: =Lookup!C876 -> 1776 | C22: =Lookup!D876 -> Slater Rd at GoTriangle Admin Office | D22: =Lookup!E876 -> C | Q22: =IF(H22="",0,1)+IF(L22="",0,1)+IF(P22="",0,1) -> 0
B23: =Lookup!C777 -> 1777 | C23: =Lookup!D777 -> Slater Rd at Sheraton Hotel | D23: =Lookup!E777 -> C | Q23: =IF(H23="",0,1)+IF(L23="",0,1)+IF(P23="",0,1) -> 0
B24: =Lookup!C500 -> 1781 | C24: =Lookup!D500 -> NC 54 at Revere Rd (EB) | D24: =Lookup!E500 -> C | Q24: =IF(H24="",0,1)+IF(L24="",0,1)+IF(P24="",0,1) -> 0
B25: =Lookup!C738 -> 1804 | C25: =Lookup!D738 -> Renaissance Pkwy at Leonardo Dr (WB) | D25: =Lookup!E738 -> C | Q25: =IF(H25="",0,1)+IF(L25="",0,1)+IF(P25="",0,1) -> 0
B26: =Lookup!C374 -> 1805 | C26: =Lookup!D374 -> NC 54 at Amhurst St | D26: =Lookup!E374 -> C | Q26: =IF(H26="",0,1)+IF(L26="",0,1)+IF(P26="",0,1) -> 0
B27: =Lookup!C893 -> 1860 | C27: =Lookup!D893 -> NC 54 at Park Dr (EB) | D27: =Lookup!E893 -> C | Q27: =IF(H27="",0,1)+IF(L27="",0,1)+IF(P27="",0,1) -> 0
B28: =Lookup!C888 -> 1861 | C28: =Lookup!D888 -> NC 54 at Park Dr (First Citizens Bank) | D28: =Lookup!E888 -> C | Q28: =IF(H28="",0,1)+IF(L28="",0,1)+IF(P28="",0,1) -> 0
B29: =Lookup!C879 -> 1863 | C29: =Lookup!D879 -> NC 54 at Park Office Dr (The Frontier) | D29: =Lookup!E879 -> C | Q29: =IF(H29="",0,1)+IF(L29="",0,1)+IF(P29="",0,1) -> 0
B30: =Lookup!C857 -> 1864 | C30: =Lookup!D857 -> NC 54 at Research Triangle High School | D30: =Lookup!E857 -> C | Q30: =IF(H30="",0,1)+IF(L30="",0,1)+IF(P30="",0,1) -> 0
B31: =Lookup!C740 -> 1865 | C31: =Lookup!D740 -> NC 54 at Triangle Dr (WB) | D31: =Lookup!E740 -> C | Q31: =IF(H31="",0,1)+IF(L31="",0,1)+IF(P31="",0,1) -> 0
B32: =Lookup!C353 -> 1866 | C32: =Lookup!D353 -> NC 54 at Triangle Dr (EB) | D32: =Lookup!E353 -> C | Q32: =IF(H32="",0,1)+IF(L32="",0,1)+IF(P32="",0,1) -> 0
B33: =Lookup!C202 -> 1892 | C33: =Lookup!D202 -> Fayetteville Rd at Renaissance Pkwy | D33: =Lookup!E202 -> B | E33: Cleaning + Trash Removal | F33: 45775 | H33: 45775 | Q33: =IF(H33="",0,1)+IF(L33="",0,1)+IF(P33="",0,1) -> 1
B34: =Lookup!C479 -> 1893 | C34: =Lookup!D479 -> NC 54 at The Hamptons Apts (EB) | D34: =Lookup!E479 -> C | Q34: =IF(H34="",0,1)+IF(L34="",0,1)+IF(P34="",0,1) -> 0
B35: =Lookup!C61 -> 1901 | C35: =Lookup!D61 -> McFarland Dr at Witherspoon Blvd (Patte | D35: =Lookup!E61 -> A | E35: Cleaning + Trash Removal | F35: 45775 | H35: 45775 | I35: Cleaning + Trash Removal | J35: 45779 | L35: 45779 | Q35: =IF(H35="",0,1)+IF(L35="",0,1)+IF(P35="",0,1) -> 2
B36: =Lookup!C595 -> 1914 | C36: =Lookup!D595 -> University Dr at University Pl (EB) | D36: =Lookup!E595 -> C | Q36: =IF(H36="",0,1)+IF(L36="",0,1)+IF(P36="",0,1) -> 0
B37: =Lookup!C611 -> 5002 | C37: =Lookup!D611 -> Riddle Rd at Ancroft Ave (NB) | D37: =Lookup!E611 -> C | Q37: =IF(H37="",0,1)+IF(L37="",0,1)+IF(P37="",0,1) -> 0
B38: =Lookup!C201 -> 5004 | C38: =Lookup!D201 -> Alston Ave at Main St | D38: =Lookup!E201 -> B | E38: Cleaning + Trash Removal | F38: 45776 | H38: 45776 | Q38: =IF(H38="",0,1)+IF(L38="",0,1)+IF(P38="",0,1) -> 1
B39: =Lookup!C838 -> 5005 | C39: =Lookup!D838 -> Cornwallis Rd at Industry Ln | D39: =Lookup!E838 -> C | Q39: =IF(H39="",0,1)+IF(L39="",0,1)+IF(P39="",0,1) -> 0
B40: =Lookup!C889 -> 5006 | C40: =Lookup!D889 -> Alston Ave at Durham Freeway (NB) | D40: =Lookup!E889 -> C | E40: Cleaning + Trash Removal | F40: 45778 | G40: 45778 | H40: 45778 | Q40: =IF(H40="",0,1)+IF(L40="",0,1)+IF(P40="",0,1) -> 1
B41: =Lookup!C240 -> 5008 | C41: =Lookup!D240 -> S Alston Ave at Massey Ave (NB) | D41: =Lookup!E240 -> B | E41: Inspected -Found all OK | F41: 45776 | H41: 45776 | Q41: =IF(H41="",0,1)+IF(L41="",0,1)+IF(P41="",0,1) -> 1
...

Sheet MAY 25
B1: BUS STOP MAINTENANCE TRACKER MAY 26-30 2025
B3: Bus Stop ID | C3: Bus Stop Locations | D3: Type | E3: Requested Service | F3: Service Request Received on | G3: Work Order sent to Contractor on | H3: 45803 | I3: Requested Service | J3: Service Request Received on | K3: Work Order sent to Contractor on | L3: 45805 | M3: Requested Service | N3: Service Request Received on | O3: Work Order sent to Contractor on | P3: Work Executed on (Mandatory) | Q3: Total number of Executions per Bus Stop
B4: =Lookup!C443 -> 1072 | C4: =Lookup!D443 -> Old Chapel Hill Rd at Garrett Rd (EB) | D4: =Lookup!E443 -> C | Q4: =IF(H4="",0,1)+IF(L4="",0,1)+IF(P4="",0,1) -> 0
B5: =Lookup!C776 -> 1074 | C5: =Lookup!D776 -> University Dr at American Red Cross | D5: =Lookup!E776 -> C | Q5: =IF(H5="",0,1)+IF(L5="",0,1)+IF(P5="",0,1) -> 0
B6: =Lookup!C273 -> 1075 | C6: =Lookup!D273 -> University Dr at Ivy Creek Blvd | D6: =Lookup!E273 -> B | E6: Cleaning + Trash Removal | F6: 45803 | H6: 45803 | I6: Cleaning + Trash Removal | J6: 45807 | L6: 45807 | Q6: =IF(H6="",0,1)+IF(L6="",0,1)+IF(P6="",0,1) -> 2
B7: =Lookup!C435 -> 1160 | C7: =Lookup!D435 -> NC 54 at Blanchard Rd (EB) | D7: =Lookup!E435 -> C | Q7: =IF(H7="",0,1)+IF(L7="",0,1)+IF(P7="",0,1) -> 0
B8: =Lookup!C510 -> 1161 | C8: =Lookup!D510 -> NC 54 at Residence Inn Blvd (EB) | D8: =Lookup!E510 -> C | Q8: =IF(H8="",0,1)+IF(L8="",0,1)+IF(P8="",0,1) -> 0
B9: =Lookup!C588 -> 1171 | C9: =Lookup!D588 -> NC 54 at Blanchard Rd (WB) | D9: =Lookup!E588 -> C | Q9: =IF(H9="",0,1)+IF(L9="",0,1)+IF(P9="",0,1) -> 0
B10: =Lookup!C545 -> 1175 | C10: =Lookup!D545 -> NC 54 at Fayetteville Rd (Duke Health) | D10: =Lookup!E545 -> C | Q10: =IF(H10="",0,1)+IF(L10="",0,1)+IF(P10="",0,1) -> 0
B11: =Lookup!C735 -> 1221 | C11: =Lookup!D735 -> Slater Rd at Page Rd (Imperial Point) | D11: =Lookup!E735 -> C | Q11: =IF(H11="",0,1)+IF(L11="",0,1)+IF(P11="",0,1) -> 0
B12: =Lookup!C877 -> 1222 | C12: =Lookup!D877 -> Slater Rd at Emperor Blvd (Chelsea Place) | D12: =Lookup!E877 -> C | Q12: =IF(H12="",0,1)+IF(L12="",0,1)+IF(P12="",0,1) -> 0
B13: =Lookup!C6 -> 1406 | C13: =Lookup!D6 -> Renaissance Pkwy at Southpoint Mall | D13: =Lookup!E6 -> A | E13: Cleaning + Trash Removal | F13: 45803 | H13: 45803 | I13: Cleaning + Trash Removal | J13: 45805 | L13: 45805 | Q13: =IF(H13="",0,1)+IF(L13="",0,1)+IF(P13="",0,1) -> 2
B14: =Lookup!C660 -> 1499 | C14: =Lookup!D660 -> Slater Rd at Page Rd (Coastal Credit Union) | D14: =Lookup!E660 -> C | Q14: =IF(H14="",0,1)+IF(L14="",0,1)+IF(P14="",0,1) -> 0
B15: =Lookup!C336 -> 1553 | C15: =Lookup!D336 -> Erwin Rd at Towerview Rd | D15: =Lookup!E336 -> B | E15: Cleaning + Trash Removal | F15: 45803 | H15: 45803 | Q15: =IF(H15="",0,1)+IF(L15="",0,1)+IF(P15="",0,1) -> 1
B16: =Lookup!C817 -> 1556 | C16: =Lookup!D817 -> NC 54 at New Millennium Way (EB) | D16: =Lookup!E817 -> C | Q16: =IF(H16="",0,1)+IF(L16="",0,1)+IF(P16="",0,1) -> 0
B17: =Lookup!C749 -> 1557 | C17: =Lookup!D749 -> NC 54 at New Millennium Way (WB) | D17: =Lookup!E749 -> C | Q17: =IF(H17="",0,1)+IF(L17="",0,1)+IF(P17="",0,1) -> 0
B18: =Lookup!C274 -> 1558 | C18: =Lookup!D274 -> Slater Rd at Creekstone Dr (Duke Medicine) | D18: =Lookup!E274 -> B | E18: Cleaning + Trash Removal | F18: 45797 | H18: 45797 | Q18: =IF(H18="",0,1)+IF(L18="",0,1)+IF(P18="",0,1) -> 1
B19: =Lookup!C892 -> 1563 | C19: =Lookup!D892 -> Slater Rd at Emperor Blvd (Bright Horiz | D19: =Lookup!E892 -> C | Q19: =IF(H19="",0,1)+IF(L19="",0,1)+IF(P19="",0,1) -> 0
B20: =Lookup!C565 -> 1566 | C20: =Lookup!D565 -> Slater Rd at S Miami Blvd (Zaxbys) | D20: =Lookup!E565 -> C | Q20: =IF(H20="",0,1)+IF(L20="",0,1)+IF(P20="",0,1) -> 0
B21: =Lookup!C869 -> 1732 | C21: =Lookup!D869 -> Stirrup Creek at Twin Creek Ct | D21: =Lookup!E869 -> C | Q21: =IF(H21="",0,1)+IF(L21="",0,1)+IF(P21="",0,1) -> 0
B22: =Lookup!C876 -> 1776 | C22: =Lookup!D876 -> Slater Rd at GoTriangle Admin Office | D22: =Lookup!E876 -> C | Q22: =IF(H22="",0,1)+IF(L22="",0,1)+IF(P22="",0,1) -> 0
B23: =Lookup!C777 -> 1777 | C23: =Lookup!D777 -> Slater Rd at Sheraton Hotel | D23: =Lookup!E777 -> C | Q23: =IF(H23="",0,1)+IF(L23="",0,1)+IF(P23="",0,1) -> 0
B24: =Lookup!C500 -> 1781 | C24: =Lookup!D500 -> NC 54 at Revere Rd (EB) | D24: =Lookup!E500 -> C | Q24: =IF(H24="",0,1)+IF(L24="",0,1)+IF(P24="",0,1) -> 0
B25: =Lookup!C738 -> 1804 | C25: =Lookup!D738 -> Renaissance Pkwy at Leonardo Dr (WB) | D25: =Lookup!E738 -> C | E25: Cleaning + Trash Removal | F25: 45783 | H25: 45783 | Q25: =IF(H25="",0,1)+IF(L25="",0,1)+IF(P25="",0,1) -> 1
B26: =Lookup!C374 -> 1805 | C26: =Lookup!D374 -> NC 54 at Amhurst St | D26: =Lookup!E374 -> C | Q26: =IF(H26="",0,1)+IF(L26="",0,1)+IF(P26="",0,1) -> 0
B27: =Lookup!C893 -> 1860 | C27: =Lookup!D893 -> NC 54 at Park Dr (EB) | D27: =Lookup!E893 -> C | Q27: =IF(H27="",0,1)+IF(L27="",0,1)+IF(P27="",0,1) -> 0
B28: =Lookup!C888 -> 1861 | C28: =Lookup!D888 -> NC 54 at Park Dr (First Citizens Bank) | D28: =Lookup!E888 -> C | Q28: =IF(H28="",0,1)+IF(L28="",0,1)+IF(P28="",0,1) -> 0
B29: =Lookup!C879 -> 1863 | C29: =Lookup!D879 -> NC 54 at Park Office Dr (The Frontier) | D29: =Lookup!E879 -> C | Q29: =IF(H29="",0,1)+IF(L29="",0,1)+IF(P29="",0,1) -> 0
B30: =Lookup!C857 -> 1864 | C30: =Lookup!D857 -> NC 54 at Research Triangle High School | D30: =Lookup!E857 -> C | Q30: =IF(H30="",0,1)+IF(L30="",0,1)+IF(P30="",0,1) -> 0
B31: =Lookup!C740 -> 1865 | C31: =Lookup!D740 -> NC 54 at Triangle Dr (WB) | D31: =Lookup!E740 -> C | Q31: =IF(H31="",0,1)+IF(L31="",0,1)+IF(P31="",0,1) -> 0
B32: =Lookup!C353 -> 1866 | C32: =Lookup!D353 -> NC 54 at Triangle Dr (EB) | D32: =Lookup!E353 -> C | Q32: =IF(H32="",0,1)+IF(L32="",0,1)+IF(P32="",0,1) -> 0
B33: =Lookup!C202 -> 1892 | C33: =Lookup!D202 -> Fayetteville Rd at Renaissance Pkwy | D33: =Lookup!E202 -> B | E33: Cleaning + Trash Removal | F33: 45803 | H33: 45803 | Q33: =IF(H33="",0,1)+IF(L33="",0,1)+IF(P33="",0,1) -> 1
B34: =Lookup!C479 -> 1893 | C34: =Lookup!D479 -> NC 54 at The Hamptons Apts (EB) | D34: =Lookup!E479 -> C | Q34: =IF(H34="",0,1)+IF(L34="",0,1)+IF(P34="",0,1) -> 0
B35: =Lookup!C61 -> 1901 | C35: =Lookup!D61 -> McFarland Dr at Witherspoon Blvd (Patte | D35: =Lookup!E61 -> A | E35: Cleaning + Trash Removal | F35: 45803 | H35: 45803 | I35: Cleaning + Trash Removal | J35: 45805 | L35: 45805 | Q35: =IF(H35="",0,1)+IF(L35="",0,1)+IF(P35="",0,1) -> 2
B36: =Lookup!C595 -> 1914 | C36: =Lookup!D595 -> University Dr at University Pl (EB) | D36: =Lookup!E595 -> C | Q36: =IF(H36="",0,1)+IF(L36="",0,1)+IF(P36="",0,1) -> 0
B37: =Lookup!C611 -> 5002 | C37: =Lookup!D611 -> Riddle Rd at Ancroft Ave (NB) | D37: =Lookup!E611 -> C | E37: Inspected -Found all OK | F37: 45784 | H37: 45784 | Q37: =IF(H37="",0,1)+IF(L37="",0,1)+IF(P37="",0,1) -> 1
B38: =Lookup!C201 -> 5004 | C38: =Lookup!D201 -> Alston Ave at Main St | D38: =Lookup!E201 -> B | E38: Cleaning + Trash Removal | F38: 45804 | H38: 45804 | Q38: =IF(H38="",0,1)+IF(L38="",0,1)+IF(P38="",0,1) -> 1
B39: =Lookup!C838 -> 5005 | C39: =Lookup!D838 -> Cornwallis Rd at Industry Ln | D39: =Lookup!E838 -> C | Q39: =IF(H39="",0,1)+IF(L39="",0,1)+IF(P39="",0,1) -> 0
B40: =Lookup!C889 -> 5006 | C40: =Lookup!D889 -> Alston Ave at Durham Freeway (NB) | D40: =Lookup!E889 -> C | Q40: =IF(H40="",0,1)+IF(L40="",0,1)+IF(P40="",0,1) -> 0
B41: =Lookup!C240 -> 5008 | C41: =Lookup!D240 -> S Alston Ave at Massey Ave (NB) | D41: =Lookup!E240 -> B | E41: Cleaning + Trash Removal | F41: 45804 | H41: 45804 | Q41: =IF(H41="",0,1)+IF(L41="",0,1)+IF(P41="",0,1) -> 1
...

Sheet JUN 25
B1: BUS STOP MAINTENANCE TRACKER JUNE 2025
B3: Bus Stop ID | C3: Bus Stop Locations | D3: Type | E3: Requested Service | F3: Service Request Received on | G3: Work Order sent to Contractor on | H3: Work Executed on (Mandatory) | I3: Requested Service | J3: Service Request Received on | K3: Work Order sent to Contractor on | L3: Work Executed on (Mandatory) | M3: Requested Service | N3: Service Request Received on | O3: Work Order sent to Contractor on | P3: Work Executed on (Mandatory) | Q3: Total number of Executions per Bus Stop
B4: =Lookup!C443 -> 1072 | C4: =Lookup!D443 -> Old Chapel Hill Rd at Garrett Rd (EB) | D4: =Lookup!E443 -> C | Q4: =IF(H4="",0,1)+IF(L4="",0,1)+IF(P4="",0,1) -> 0
B5: =Lookup!C776 -> 1074 | C5: =Lookup!D776 -> University Dr at American Red Cross | D5: =Lookup!E776 -> C | Q5: =IF(H5="",0,1)+IF(L5="",0,1)+IF(P5="",0,1) -> 0
B6: =Lookup!C273 -> 1075 | C6: =Lookup!D273 -> University Dr at Ivy Creek Blvd | D6: =Lookup!E273 -> B | Q6: =IF(H6="",0,1)+IF(L6="",0,1)+IF(P6="",0,1) -> 0
B7: =Lookup!C435 -> 1160 | C7: =Lookup!D435 -> NC 54 at Blanchard Rd (EB) | D7: =Lookup!E435 -> C | Q7: =IF(H7="",0,1)+IF(L7="",0,1)+IF(P7="",0,1) -> 0
B8: =Lookup!C510 -> 1161 | C8: =Lookup!D510 -> NC 54 at Residence Inn Blvd (EB) | D8: =Lookup!E510 -> C | Q8: =IF(H8="",0,1)+IF(L8="",0,1)+IF(P8="",0,1) -> 0
B9: =Lookup!C588 -> 1171 | C9: =Lookup!D588 -> NC 54 at Blanchard Rd (WB) | D9: =Lookup!E588 -> C | Q9: =IF(H9="",0,1)+IF(L9="",0,1)+IF(P9="",0,1) -> 0
B10: =Lookup!C545 -> 1175 | C10: =Lookup!D545 -> NC 54 at Fayetteville Rd (Duke Health) | D10: =Lookup!E545 -> C | Q10: =IF(H10="",0,1)+IF(L10="",0,1)+IF(P10="",0,1) -> 0
B11: =Lookup!C735 -> 1221 | C11: =Lookup!D735 -> Slater Rd at Page Rd (Imperial Point) | D11: =Lookup!E735 -> C | Q11: =IF(H11="",0,1)+IF(L11="",0,1)+IF(P11="",0,1) -> 0
B12: =Lookup!C877 -> 1222 | C12: =Lookup!D877 -> Slater Rd at Emperor Blvd (Chelsea Place) | D12: =Lookup!E877 -> C | Q12: =IF(H12="",0,1)+IF(L12="",0,1)+IF(P12="",0,1) -> 0
B13: =Lookup!C6 -> 1406 | C13: =Lookup!D6 -> Renaissance Pkwy at Southpoint Mall | D13: =Lookup!E6 -> A | Q13: =IF(H13="",0,1)+IF(L13="",0,1)+IF(P13="",0,1) -> 0
B14: =Lookup!C660 -> 1499 | C14: =Lookup!D660 -> Slater Rd at Page Rd (Coastal Credit Union) | D14: =Lookup!E660 -> C | Q14: =IF(H14="",0,1)+IF(L14="",0,1)+IF(P14="",0,1) -> 0
B15: =Lookup!C336 -> 1553 | C15: =Lookup!D336 -> Erwin Rd at Towerview Rd | D15: =Lookup!E336 -> B | Q15: =IF(H15="",0,1)+IF(L15="",0,1)+IF(P15="",0,1) -> 0
B16: =Lookup!C817 -> 1556 | C16: =Lookup!D817 -> NC 54 at New Millennium Way (EB) | D16: =Lookup!E817 -> C | Q16: =IF(H16="",0,1)+IF(L16="",0,1)+IF(P16="",0,1) -> 0
B17: =Lookup!C749 -> 1557 | C17: =Lookup!D749 -> NC 54 at New Millennium Way (WB) | D17: =Lookup!E749 -> C | Q17: =IF(H17="",0,1)+IF(L17="",0,1)+IF(P17="",0,1) -> 0
B18: =Lookup!C274 -> 1558 | C18: =Lookup!D274 -> Slater Rd at Creekstone Dr (Duke Medicine) | D18: =Lookup!E274 -> B | Q18: =IF(H18="",0,1)+IF(L18="",0,1)+IF(P18="",0,1) -> 0
B19: =Lookup!C892 -> 1563 | C19: =Lookup!D892 -> Slater Rd at Emperor Blvd (Bright Horiz | D19: =Lookup!E892 -> C | Q19: =IF(H19="",0,1)+IF(L19="",0,1)+IF(P19="",0,1) -> 0
B20: =Lookup!C565 -> 1566 | C20: =Lookup!D565 -> Slater Rd at S Miami Blvd (Zaxbys) | D20: =Lookup!E565 -> C | Q20: =IF(H20="",0,1)+IF(L20="",0,1)+IF(P20="",0,1) -> 0
B21: =Lookup!C869 -> 1732 | C21: =Lookup!D869 -> Stirrup Creek at Twin Creek Ct | D21: =Lookup!E869 -> C | Q21: =IF(H21="",0,1)+IF(L21="",0,1)+IF(P21="",0,1) -> 0
B22: =Lookup!C876 -> 1776 | C22: =Lookup!D876 -> Slater Rd at GoTriangle Admin Office | D22: =Lookup!E876 -> C | Q22: =IF(H22="",0,1)+IF(L22="",0,1)+IF(P22="",0,1) -> 0
B23: =Lookup!C777 -> 1777 | C23: =Lookup!D777 -> Slater Rd at Sheraton Hotel | D23: =Lookup!E777 -> C | Q23: =IF(H23="",0,1)+IF(L23="",0,1)+IF(P23="",0,1) -> 0
B24: =Lookup!C500 -> 1781 | C24: =Lookup!D500 -> NC 54 at Revere Rd (EB) | D24: =Lookup!E500 -> C | Q24: =IF(H24="",0,1)+IF(L24="",0,1)+IF(P24="",0,1) -> 0
B25: =Lookup!C738 -> 1804 | C25: =Lookup!D738 -> Renaissance Pkwy at Leonardo Dr (WB) | D25: =Lookup!E738 -> C | Q25: =IF(H25="",0,1)+IF(L25="",0,1)+IF(P25="",0,1) -> 0
B26: =Lookup!C374 -> 1805 | C26: =Lookup!D374 -> NC 54 at Amhurst St | D26: =Lookup!E374 -> C | Q26: =IF(H26="",0,1)+IF(L26="",0,1)+IF(P26="",0,1) -> 0
B27: =Lookup!C893 -> 1860 | C27: =Lookup!D893 -> NC 54 at Park Dr (EB) | D27: =Lookup!E893 -> C | Q27: =IF(H27="",0,1)+IF(L27="",0,1)+IF(P27="",0,1) -> 0
B28: =Lookup!C888 -> 1861 | C28: =Lookup!D888 -> NC 54 at Park Dr (First Citizens Bank) | D28: =Lookup!E888 -> C | Q28: =IF(H28="",0,1)+IF(L28="",0,1)+IF(P28="",0,1) -> 0
B29: =Lookup!C879 -> 1863 | C29: =Lookup!D879 -> NC 54 at Park Office Dr (The Frontier) | D29: =Lookup!E879 -> C | Q29: =IF(H29="",0,1)+IF(L29="",0,1)+IF(P29="",0,1) -> 0
B30: =Lookup!C857 -> 1864 | C30: =Lookup!D857 -> NC 54 at Research Triangle High School | D30: =Lookup!E857 -> C | Q30: =IF(H30="",0,1)+IF(L30="",0,1)+IF(P30="",0,1) -> 0
B31: =Lookup!C740 -> 1865 | C31: =Lookup!D740 -> NC 54 at Triangle Dr (WB) | D31: =Lookup!E740 -> C | Q31: =IF(H31="",0,1)+IF(L31="",0,1)+IF(P31="",0,1) -> 0
B32: =Lookup!C353 -> 1866 | C32: =Lookup!D353 -> NC 54 at Triangle Dr (EB) | D32: =Lookup!E353 -> C | Q32: =IF(H32="",0,1)+IF(L32="",0,1)+IF(P32="",0,1) -> 0
B33: =Lookup!C202 -> 1892 | C33: =Lookup!D202 -> Fayetteville Rd at Renaissance Pkwy | D33: =Lookup!E202 -> B | Q33: =IF(H33="",0,1)+IF(L33="",0,1)+IF(P33="",0,1) -> 0
B34: =Lookup!C479 -> 1893 | C34: =Lookup!D479 -> NC 54 at The Hamptons Apts (EB) | D34: =Lookup!E479 -> C | Q34: =IF(H34="",0,1)+IF(L34="",0,1)+IF(P34="",0,1) -> 0
B35: =Lookup!C61 -> 1901 | C35: =Lookup!D61 -> McFarland Dr at Witherspoon Blvd (Patte | D35: =Lookup!E61 -> A | Q35: =IF(H35="",0,1)+IF(L35="",0,1)+IF(P35="",0,1) -> 0
B36: =Lookup!C595 -> 1914 | C36: =Lookup!D595 -> University Dr at University Pl (EB) | D36: =Lookup!E595 -> C | Q36: =IF(H36="",0,1)+IF(L36="",0,1)+IF(P36="",0,1) -> 0
B37: =Lookup!C611 -> 5002 | C37: =Lookup!D611 -> Riddle Rd at Ancroft Ave (NB) | D37: =Lookup!E611 -> C | Q37: =IF(H37="",0,1)+IF(L37="",0,1)+IF(P37="",0,1) -> 0
B38: =Lookup!C201 -> 5004 | C38: =Lookup!D201 -> Alston Ave at Main St | D38: =Lookup!E201 -> B | Q38: =IF(H38="",0,1)+IF(L38="",0,1)+IF(P38="",0,1) -> 0
B39: =Lookup!C838 -> 5005 | C39: =Lookup!D838 -> Cornwallis Rd at Industry Ln | D39: =Lookup!E838 -> C | Q39: =IF(H39="",0,1)+IF(L39="",0,1)+IF(P39="",0,1) -> 0
B40: =Lookup!C889 -> 5006 | C40: =Lookup!D889 -> Alston Ave at Durham Freeway (NB) | D40: =Lookup!E889 -> C | Q40: =IF(H40="",0,1)+IF(L40="",0,1)+IF(P40="",0,1) -> 0
B41: =Lookup!C240 -> 5008 | C41: =Lookup!D240 -> S Alston Ave at Massey Ave (NB) | D41: =Lookup!E240 -> B | Q41: =IF(H41="",0,1)+IF(L41="",0,1)+IF(P41="",0,1) -> 0
...

Sheet JUL 25
B1: BUS STOP MAINTENANCE TRACKER JULY 2025
B3: Bus Stop ID | C3: Bus Stop Locations | D3: Type | E3: Requested Service | F3: Service Request Received on | G3: Work Order sent to Contractor on | H3: Work Executed on (Mandatory) | I3: Requested Service | J3: Service Request Received on | K3: Work Order sent to Contractor on | L3: Work Executed on (Mandatory) | M3: Requested Service | N3: Service Request Received on | O3: Work Order sent to Contractor on | P3: Work Executed on (Mandatory) | Q3: Total number of Executions per Bus Stop
B4: =Lookup!C443 -> 1072 | C4: =Lookup!D443 -> Old Chapel Hill Rd at Garrett Rd (EB) | D4: =Lookup!E443 -> C | Q4: =IF(H4="",0,1)+IF(L4="",0,1)+IF(P4="",0,1) -> 0
B5: =Lookup!C776 -> 1074 | C5: =Lookup!D776 -> University Dr at American Red Cross | D5: =Lookup!E776 -> C | Q5: =IF(H5="",0,1)+IF(L5="",0,1)+IF(P5="",0,1) -> 0
B6: =Lookup!C273 -> 1075 | C6: =Lookup!D273 -> University Dr at Ivy Creek Blvd | D6: =Lookup!E273 -> B | Q6: =IF(H6="",0,1)+IF(L6="",0,1)+IF(P6="",0,1) -> 0
B7: =Lookup!C435 -> 1160 | C7: =Lookup!D435 -> NC 54 at Blanchard Rd (EB) | D7: =Lookup!E435 -> C | Q7: =IF(H7="",0,1)+IF(L7="",0,1)+IF(P7="",0,1) -> 0
B8: =Lookup!C510 -> 1161 | C8: =Lookup!D510 -> NC 54 at Residence Inn Blvd (EB) | D8: =Lookup!E510 -> C | Q8: =IF(H8="",0,1)+IF(L8="",0,1)+IF(P8="",0,1) -> 0
B9: =Lookup!C588 -> 1171 | C9: =Lookup!D588 -> NC 54 at Blanchard Rd (WB) | D9: =Lookup!E588 -> C | Q9: =IF(H9="",0,1)+IF(L9="",0,1)+IF(P9="",0,1) -> 0
B10: =Lookup!C545 -> 1175 | C10: =Lookup!D545 -> NC 54 at Fayetteville Rd (Duke Health) | D10: =Lookup!E545 -> C | Q10: =IF(H10="",0,1)+IF(L10="",0,1)+IF(P10="",0,1) -> 0
B11: =Lookup!C735 -> 1221 | C11: =Lookup!D735 -> Slater Rd at Page Rd (Imperial Point) | D11: =Lookup!E735 -> C | Q11: =IF(H11="",0,1)+IF(L11="",0,1)+IF(P11="",0,1) -> 0
B12: =Lookup!C877 -> 1222 | C12: =Lookup!D877 -> Slater Rd at Emperor Blvd (Chelsea Place) | D12: =Lookup!E877 -> C | Q12: =IF(H12="",0,1)+IF(L12="",0,1)+IF(P12="",0,1) -> 0
B13: =Lookup!C6 -> 1406 | C13: =Lookup!D6 -> Renaissance Pkwy at Southpoint Mall | D13: =Lookup!E6 -> A | Q13: =IF(H13="",0,1)+IF(L13="",0,1)+IF(P13="",0,1) -> 0
B14: =Lookup!C660 -> 1499 | C14: =Lookup!D660 -> Slater Rd at Page Rd (Coastal Credit Union) | D14: =Lookup!E660 -> C | Q14: =IF(H14="",0,1)+IF(L14="",0,1)+IF(P14="",0,1) -> 0
B15: =Lookup!C336 -> 1553 | C15: =Lookup!D336 -> Erwin Rd at Towerview Rd | D15: =Lookup!E336 -> B | Q15: =IF(H15="",0,1)+IF(L15="",0,1)+IF(P15="",0,1) -> 0
B16: =Lookup!C817 -> 1556 | C16: =Lookup!D817 -> NC 54 at New Millennium Way (EB) | D16: =Lookup!E817 -> C | Q16: =IF(H16="",0,1)+IF(L16="",0,1)+IF(P16="",0,1) -> 0
B17: =Lookup!C749 -> 1557 | C17: =Lookup!D749 -> NC 54 at New Millennium Way (WB) | D17: =Lookup!E749 -> C | Q17: =IF(H17="",0,1)+IF(L17="",0,1)+IF(P17="",0,1) -> 0
B18: =Lookup!C274 -> 1558 | C18: =Lookup!D274 -> Slater Rd at Creekstone Dr (Duke Medicine) | D18: =Lookup!E274 -> B | Q18: =IF(H18="",0,1)+IF(L18="",0,1)+IF(P18="",0,1) -> 0
B19: =Lookup!C892 -> 1563 | C19: =Lookup!D892 -> Slater Rd at Emperor Blvd (Bright Horiz | D19: =Lookup!E892 -> C | Q19: =IF(H19="",0,1)+IF(L19="",0,1)+IF(P19="",0,1) -> 0
B20: =Lookup!C565 -> 1566 | C20: =Lookup!D565 -> Slater Rd at S Miami Blvd (Zaxbys) | D20: =Lookup!E565 -> C | Q20: =IF(H20="",0,1)+IF(L20="",0,1)+IF(P20="",0,1) -> 0
B21: =Lookup!C869 -> 1732 | C21: =Lookup!D869 -> Stirrup Creek at Twin Creek Ct | D21: =Lookup!E869 -> C | Q21: =IF(H21="",0,1)+IF(L21="",0,1)+IF(P21="",0,1) -> 0
B22: =Lookup!C876 -> 1776 | C22: =Lookup!D876 -> Slater Rd at GoTriangle Admin Office | D22: =Lookup!E876 -> C | Q22: =IF(H22="",0,1)+IF(L22="",0,1)+IF(P22="",0,1) -> 0
B23: =Lookup!C777 -> 1777 | C23: =Lookup!D777 -> Slater Rd at Sheraton Hotel | D23: =Lookup!E777 -> C | Q23: =IF(H23="",0,1)+IF(L23="",0,1)+IF(P23="",0,1) -> 0
B24: =Lookup!C500 -> 1781 | C24: =Lookup!D500 -> NC 54 at Revere Rd (EB) | D24: =Lookup!E500 -> C | Q24: =IF(H24="",0,1)+IF(L24="",0,1)+IF(P24="",0,1) -> 0
B25: =Lookup!C738 -> 1804 | C25: =Lookup!D738 -> Renaissance Pkwy at Leonardo Dr (WB) | D25: =Lookup!E738 -> C | Q25: =IF(H25="",0,1)+IF(L25="",0,1)+IF(P25="",0,1) -> 0
B26: =Lookup!C374 -> 1805 | C26: =Lookup!D374 -> NC 54 at Amhurst St | D26: =Lookup!E374 -> C | Q26: =IF(H26="",0,1)+IF(L26="",0,1)+IF(P26="",0,1) -> 0
B27: =Lookup!C893 -> 1860 | C27: =Lookup!D893 -> NC 54 at Park Dr (EB) | D27: =Lookup!E893 -> C | Q27: =IF(H27="",0,1)+IF(L27="",0,1)+IF(P27="",0,1) -> 0
B28: =Lookup!C888 -> 1861 | C28: =Lookup!D888 -> NC 54 at Park Dr (First Citizens Bank) | D28: =Lookup!E888 -> C | Q28: =IF(H28="",0,1)+IF(L28="",0,1)+IF(P28="",0,1) -> 0
B29: =Lookup!C879 -> 1863 | C29: =Lookup!D879 -> NC 54 at Park Office Dr (The Frontier) | D29: =Lookup!E879 -> C | Q29: =IF(H29="",0,1)+IF(L29="",0,1)+IF(P29="",0,1) -> 0
B30: =Lookup!C857 -> 1864 | C30: =Lookup!D857 -> NC 54 at Research Triangle High School | D30: =Lookup!E857 -> C | Q30: =IF(H30="",0,1)+IF(L30="",0,1)+IF(P30="",0,1) -> 0
B31: =Lookup!C740 -> 1865 | C31: =Lookup!D740 -> NC 54 at Triangle Dr (WB) | D31: =Lookup!E740 -> C | Q31: =IF(H31="",0,1)+IF(L31="",0,1)+IF(P31="",0,1) -> 0
B32: =Lookup!C353 -> 1866 | C32: =Lookup!D353 -> NC 54 at Triangle Dr (EB) | D32: =Lookup!E353 -> C | Q32: =IF(H32="",0,1)+IF(L32="",0,1)+IF(P32="",0,1) -> 0
B33: =Lookup!C202 -> 1892 | C33: =Lookup!D202 -> Fayetteville Rd at Renaissance Pkwy | D33: =Lookup!E202 -> B | Q33: =IF(H33="",0,1)+IF(L33="",0,1)+IF(P33="",0,1) -> 0
B34: =Lookup!C479 -> 1893 | C34: =Lookup!D479 -> NC 54 at The Hamptons Apts (EB) | D34: =Lookup!E479 -> C | Q34: =IF(H34="",0,1)+IF(L34="",0,1)+IF(P34="",0,1) -> 0
B35: =Lookup!C61 -> 1901 | C35: =Lookup!D61 -> McFarland Dr at Witherspoon Blvd (Patte | D35: =Lookup!E61 -> A | Q35: =IF(H35="",0,1)+IF(L35="",0,1)+IF(P35="",0,1) -> 0
B36: =Lookup!C595 -> 1914 | C36: =Lookup!D595 -> University Dr at University Pl (EB) | D36: =Lookup!E595 -> C | Q36: =IF(H36="",0,1)+IF(L36="",0,1)+IF(P36="",0,1) -> 0
B37: =Lookup!C611 -> 5002 | C37: =Lookup!D611 -> Riddle Rd at Ancroft Ave (NB) | D37: =Lookup!E611 -> C | Q37: =IF(H37="",0,1)+IF(L37="",0,1)+IF(P37="",0,1) -> 0
B38: =Lookup!C201 -> 5004 | C38: =Lookup!D201 -> Alston Ave at Main St | D38: =Lookup!E201 -> B | Q38: =IF(H38="",0,1)+IF(L38="",0,1)+IF(P38="",0,1) -> 0
B39: =Lookup!C838 -> 5005 | C39: =Lookup!D838 -> Cornwallis Rd at Industry Ln | D39: =Lookup!E838 -> C | Q39: =IF(H39="",0,1)+IF(L39="",0,1)+IF(P39="",0,1) -> 0
B40: =Lookup!C889 -> 5006 | C40: =Lookup!D889 -> Alston Ave at Durham Freeway (NB) | D40: =Lookup!E889 -> C | Q40: =IF(H40="",0,1)+IF(L40="",0,1)+IF(P40="",0,1) -> 0
B41: =Lookup!C240 -> 5008 | C41: =Lookup!D240 -> S Alston Ave at Massey Ave (NB) | D41: =Lookup!E240 -> B | Q41: =IF(H41="",0,1)+IF(L41="",0,1)+IF(P41="",0,1) -> 0
...

Sheet AUG 25
B1: BUS STOP MAINTENANCE TRACKER AUGUST 2025
B3: Bus Stop ID | C3: Bus Stop Locations | D3: Type | E3: Requested Service | F3: Service Request Received on | G3: Work Order sent to Contractor on | H3: Work Executed on (Mandatory) | I3: Requested Service | J3: Service Request Received on | K3: Work Order sent to Contractor on | L3: Work Executed on (Mandatory) | M3: Requested Service | N3: Service Request Received on | O3: Work Order sent to Contractor on | P3: Work Executed on (Mandatory) | Q3: Total number of Executions per Bus Stop
B4: =Lookup!C443 -> 1072 | C4: =Lookup!D443 -> Old Chapel Hill Rd at Garrett Rd (EB) | D4: =Lookup!E443 -> C | Q4: =IF(H4="",0,1)+IF(L4="",0,1)+IF(P4="",0,1) -> 0
B5: =Lookup!C776 -> 1074 | C5: =Lookup!D776 -> University Dr at American Red Cross | D5: =Lookup!E776 -> C | Q5: =IF(H5="",0,1)+IF(L5="",0,1)+IF(P5="",0,1) -> 0
B6: =Lookup!C273 -> 1075 | C6: =Lookup!D273 -> University Dr at Ivy Creek Blvd | D6: =Lookup!E273 -> B | Q6: =IF(H6="",0,1)+IF(L6="",0,1)+IF(P6="",0,1) -> 0
B7: =Lookup!C435 -> 1160 | C7: =Lookup!D435 -> NC 54 at Blanchard Rd (EB) | D7: =Lookup!E435 -> C | Q7: =IF(H7="",0,1)+IF(L7="",0,1)+IF(P7="",0,1) -> 0
B8: =Lookup!C510 -> 1161 | C8: =Lookup!D510 -> NC 54 at Residence Inn Blvd (EB) | D8: =Lookup!E510 -> C | Q8: =IF(H8="",0,1)+IF(L8="",0,1)+IF(P8="",0,1) -> 0
B9: =Lookup!C588 -> 1171 | C9: =Lookup!D588 -> NC 54 at Blanchard Rd (WB) | D9: =Lookup!E588 -> C | Q9: =IF(H9="",0,1)+IF(L9="",0,1)+IF(P9="",0,1) -> 0
B10: =Lookup!C545 -> 1175 | C10: =Lookup!D545 -> NC 54 at Fayetteville Rd (Duke Health) | D10: =Lookup!E545 -> C | Q10: =IF(H10="",0,1)+IF(L10="",0,1)+IF(P10="",0,1) -> 0
B11: =Lookup!C735 -> 1221 | C11: =Lookup!D735 -> Slater Rd at Page Rd (Imperial Point) | D11: =Lookup!E735 -> C | Q11: =IF(H11="",0,1)+IF(L11="",0,1)+IF(P11="",0,1) -> 0
B12: =Lookup!C877 -> 1222 | C12: =Lookup!D877 -> Slater Rd at Emperor Blvd (Chelsea Place) | D12: =Lookup!E877 -> C | Q12: =IF(H12="",0,1)+IF(L12="",0,1)+IF(P12="",0,1) -> 0
B13: =Lookup!C6 -> 1406 | C13: =Lookup!D6 -> Renaissance Pkwy at Southpoint Mall | D13: =Lookup!E6 -> A | Q13: =IF(H13="",0,1)+IF(L13="",0,1)+IF(P13="",0,1) -> 0
B14: =Lookup!C660 -> 1499 | C14: =Lookup!D660 -> Slater Rd at Page Rd (Coastal Credit Union) | D14: =Lookup!E660 -> C | Q14: =IF(H14="",0,1)+IF(L14="",0,1)+IF(P14="",0,1) -> 0
B15: =Lookup!C336 -> 1553 | C15: =Lookup!D336 -> Erwin Rd at Towerview Rd | D15: =Lookup!E336 -> B | Q15: =IF(H15="",0,1)+IF(L15="",0,1)+IF(P15="",0,1) -> 0
